Workbook

Sheet Read Me
B1: Eschool - Functional Test Plan
B2: Scope: everything built so far (Oct 2026 build, includes Admissions 'pick an existing parent')
B4: Purpose | C4: Manual functional test of the completed modules. Work through the 'Test Cases' sheet top to bottom; each row is one check.
B5: Modules covered | C5: Login & Layout, Reusable Components, Class Sections, Subjects, Teachers, Parents, Admissions (incl. existing-parent picker), Students, Attendance, Documents, Users & Staff, Roles & Permissions, My Account, School Settings, Dashboard, role-based access, end-to-end flows, non-functional checks.
B6: NOT in scope | C6: Modules not built yet (Reports, Timetable, Fees, Exams, Results, Library, Notices, PTM, Calendar, Transport, Helpdesk, etc.): the sidebar items open the dashboard on purpose. Student / Parent portal logins are not built.
B7: Environment | C7: Web app: http://localhost:5173 - API: https://localhost:7100 - use a TEST database, never real data. Keep browser DevTools open (Console + Network): any red console error or HTTP 500 is a defect on its own.
B8: Test data | C8: All test records should start with 'ZT' (e.g. 'ZT Class A') so they are easy to find and delete. See sheet 'Test Data' for the users to create and sample values.
B9: How to execute | C9: 1) Filter 'Test Cases' by Module (use the filter arrows in row 1). 2) Do the steps. 3) Fill the yellow columns: Actual Result (only when different or useful), Status, Tested By, Date, Defect ID, Comments. 4) For every Fail, add a row in 'Defect Log' and put its ID in the test row.
B10: Status values | C10: Not Run (default) | Pass | Fail | Blocked (cannot test because of another defect) | N/A (not applicable)
B11: Type / Priority | C11: Type: Functional, Validation (bad input), Negative (should be refused), Security (permissions / data exposure), UI, Exploratory (the correct behaviour is not fixed: describe what you see). Priority: High = core flow or security, run first; Medium; Low.
B12: Roles | C12: Cases name the role to log in as. Admin sees everything. Clerk, Supervisor and Teacher are limited roles (create them in Users & Staff; see 'Test Data'). 'Role without X' means create a custom role in Roles & Permissions that lacks permission X.
B13: Known limitations | C13: 1) Attendance 'today' currently follows UTC, so between 00:00 and 04:00 Abu Dhabi time it can show yesterday (fix planned: F2). 2) Parent e-mail uniqueness is not enforced (PAR-14). 3) Lists load fully (no server paging yet): expect slowness only at very large volumes. 4) Fee, report-card and attendance-report buttons on students show 'not yet available'.
B14: Summary | C14: The 'Summary' sheet counts results automatically from the Status column. Do not type in it.
B16: Colour key
B17: Yellow cells | C17: You fill these in (Actual Result, Status, Tested By, Date, Defect ID, Comments).
B18: Status colours | C18: Pass = green, Fail = red, Blocked = orange, Not Run = grey (automatic).

Sheet Summary
A1: Test Execution Summary
A2: Calculated automatically from the Status column of 'Test Cases'.
A4: Module | B4: Total | C4: Pass | D4: Fail | E4: Blocked | F4: N/A | G4: Not Run | H4: % Executed | I4: % Pass (of executed)
A5: Login & Layout | B5: =COUNTIF('Test Cases'!$B$2:$B$336,$A5) -> 26 | C5: =COUNTIFS('Test Cases'!$B$2:$B$336,$A5,'Test Cases'!$K$2:$K$336,"Pass") -> 0 | D5: =COUNTIFS('Test Cases'!$B$2:$B$336,$A5,'Test Cases'!$K$2:$K$336,"Fail") -> 0 | E5: =COUNTIFS('Test Cases'!$B$2:$B$336,$A5,'Test Cases'!$K$2:$K$336,"Blocked") -> 0 | F5: =COUNTIFS('Test Cases'!$B$2:$B$336,$A5,'Test Cases'!$K$2:$K$336,"N/A") -> 0 | G5: =COUNTIFS('Test Cases'!$B$2:$B$336,$A5,'Test Cases'!$K$2:$K$336,"Not Run") -> 26 | H5: =IFERROR((B5-G5-F5)/(B5-F5),0) -> 0 | I5: =IFERROR(C5/(C5+D5),0) -> 0
A6: Reusable Components | B6: =COUNTIF('Test Cases'!$B$2:$B$336,$A6) -> 12 | C6: =COUNTIFS('Test Cases'!$B$2:$B$336,$A6,'Test Cases'!$K$2:$K$336,"Pass") -> 0 | D6: =COUNTIFS('Test Cases'!$B$2:$B$336,$A6,'Test Cases'!$K$2:$K$336,"Fail") -> 0 | E6: =COUNTIFS('Test Cases'!$B$2:$B$336,$A6,'Test Cases'!$K$2:$K$336,"Blocked") -> 0 | F6: =COUNTIFS('Test Cases'!$B$2:$B$336,$A6,'Test Cases'!$K$2:$K$336,"N/A") -> 0 | G6: =COUNTIFS('Test Cases'!$B$2:$B$336,$A6,'Test Cases'!$K$2:$K$336,"Not Run") -> 12 | H6: =IFERROR((B6-G6-F6)/(B6-F6),0) -> 0 | I6: =IFERROR(C6/(C6+D6),0) -> 0
A7: Class Sections | B7: =COUNTIF('Test Cases'!$B$2:$B$336,$A7) -> 15 | C7: =COUNTIFS('Test Cases'!$B$2:$B$336,$A7,'Test Cases'!$K$2:$K$336,"Pass") -> 0 | D7: =COUNTIFS('Test Cases'!$B$2:$B$336,$A7,'Test Cases'!$K$2:$K$336,"Fail") -> 0 | E7: =COUNTIFS('Test Cases'!$B$2:$B$336,$A7,'Test Cases'!$K$2:$K$336,"Blocked") -> 0 | F7: =COUNTIFS('Test Cases'!$B$2:$B$336,$A7,'Test Cases'!$K$2:$K$336,"N/A") -> 0 | G7: =COUNTIFS('Test Cases'!$B$2:$B$336,$A7,'Test Cases'!$K$2:$K$336,"Not Run") -> 15 | H7: =IFERROR((B7-G7-F7)/(B7-F7),0) -> 0 | I7: =IFERROR(C7/(C7+D7),0) -> 0
A8: Subjects | B8: =COUNTIF('Test Cases'!$B$2:$B$336,$A8) -> 11 | C8: =COUNTIFS('Test Cases'!$B$2:$B$336,$A8,'Test Cases'!$K$2:$K$336,"Pass") -> 0 | D8: =COUNTIFS('Test Cases'!$B$2:$B$336,$A8,'Test Cases'!$K$2:$K$336,"Fail") -> 0 | E8: =COUNTIFS('Test Cases'!$B$2:$B$336,$A8,'Test Cases'!$K$2:$K$336,"Blocked") -> 0 | F8: =COUNTIFS('Test Cases'!$B$2:$B$336,$A8,'Test Cases'!$K$2:$K$336,"N/A") -> 0 | G8: =COUNTIFS('Test Cases'!$B$2:$B$336,$A8,'Test Cases'!$K$2:$K$336,"Not Run") -> 11 | H8: =IFERROR((B8-G8-F8)/(B8-F8),0) -> 0 | I8: =IFERROR(C8/(C8+D8),0) -> 0
A9: Teachers | B9: =COUNTIF('Test Cases'!$B$2:$B$336,$A9) -> 18 | C9: =COUNTIFS('Test Cases'!$B$2:$B$336,$A9,'Test Cases'!$K$2:$K$336,"Pass") -> 0 | D9: =COUNTIFS('Test Cases'!$B$2:$B$336,$A9,'Test Cases'!$K$2:$K$336,"Fail") -> 0 | E9: =COUNTIFS('Test Cases'!$B$2:$B$336,$A9,'Test Cases'!$K$2:$K$336,"Blocked") -> 0 | F9: =COUNTIFS('Test Cases'!$B$2:$B$336,$A9,'Test Cases'!$K$2:$K$336,"N/A") -> 0 | G9: =COUNTIFS('Test Cases'!$B$2:$B$336,$A9,'Test Cases'!$K$2:$K$336,"Not Run") -> 18 | H9: =IFERROR((B9-G9-F9)/(B9-F9),0) -> 0 | I9: =IFERROR(C9/(C9+D9),0) -> 0
A10: Parents | B10: =COUNTIF('Test Cases'!$B$2:$B$336,$A10) -> 19 | C10: =COUNTIFS('Test Cases'!$B$2:$B$336,$A10,'Test Cases'!$K$2:$K$336,"Pass") -> 0 | D10: =COUNTIFS('Test Cases'!$B$2:$B$336,$A10,'Test Cases'!$K$2:$K$336,"Fail") -> 0 | E10: =COUNTIFS('Test Cases'!$B$2:$B$336,$A10,'Test Cases'!$K$2:$K$336,"Blocked") -> 0 | F10: =COUNTIFS('Test Cases'!$B$2:$B$336,$A10,'Test Cases'!$K$2:$K$336,"N/A") -> 0 | G10: =COUNTIFS('Test Cases'!$B$2:$B$336,$A10,'Test Cases'!$K$2:$K$336,"Not Run") -> 19 | H10: =IFERROR((B10-G10-F10)/(B10-F10),0) -> 0 | I10: =IFERROR(C10/(C10+D10),0) -> 0
A11: Admissions | B11: =COUNTIF('Test Cases'!$B$2:$B$336,$A11) -> 60 | C11: =COUNTIFS('Test Cases'!$B$2:$B$336,$A11,'Test Cases'!$K$2:$K$336,"Pass") -> 0 | D11: =COUNTIFS('Test Cases'!$B$2:$B$336,$A11,'Test Cases'!$K$2:$K$336,"Fail") -> 0 | E11: =COUNTIFS('Test Cases'!$B$2:$B$336,$A11,'Test Cases'!$K$2:$K$336,"Blocked") -> 0 | F11: =COUNTIFS('Test Cases'!$B$2:$B$336,$A11,'Test Cases'!$K$2:$K$336,"N/A") -> 0 | G11: =COUNTIFS('Test Cases'!$B$2:$B$336,$A11,'Test Cases'!$K$2:$K$336,"Not Run") -> 60 | H11: =IFERROR((B11-G11-F11)/(B11-F11),0) -> 0 | I11: =IFERROR(C11/(C11+D11),0) -> 0
A12: Students | B12: =COUNTIF('Test Cases'!$B$2:$B$336,$A12) -> 45 | C12: =COUNTIFS('Test Cases'!$B$2:$B$336,$A12,'Test Cases'!$K$2:$K$336,"Pass") -> 0 | D12: =COUNTIFS('Test Cases'!$B$2:$B$336,$A12,'Test Cases'!$K$2:$K$336,"Fail") -> 0 | E12: =COUNTIFS('Test Cases'!$B$2:$B$336,$A12,'Test Cases'!$K$2:$K$336,"Blocked") -> 0 | F12: =COUNTIFS('Test Cases'!$B$2:$B$336,$A12,'Test Cases'!$K$2:$K$336,"N/A") -> 0 | G12: =COUNTIFS('Test Cases'!$B$2:$B$336,$A12,'Test Cases'!$K$2:$K$336,"Not Run") -> 45 | H12: =IFERROR((B12-G12-F12)/(B12-F12),0) -> 0 | I12: =IFERROR(C12/(C12+D12),0) -> 0
A13: Attendance | B13: =COUNTIF('Test Cases'!$B$2:$B$336,$A13) -> 26 | C13: =COUNTIFS('Test Cases'!$B$2:$B$336,$A13,'Test Cases'!$K$2:$K$336,"Pass") -> 0 | D13: =COUNTIFS('Test Cases'!$B$2:$B$336,$A13,'Test Cases'!$K$2:$K$336,"Fail") -> 0 | E13: =COUNTIFS('Test Cases'!$B$2:$B$336,$A13,'Test Cases'!$K$2:$K$336,"Blocked") -> 0 | F13: =COUNTIFS('Test Cases'!$B$2:$B$336,$A13,'Test Cases'!$K$2:$K$336,"N/A") -> 0 | G13: =COUNTIFS('Test Cases'!$B$2:$B$336,$A13,'Test Cases'!$K$2:$K$336,"Not Run") -> 26 | H13: =IFERROR((B13-G13-F13)/(B13-F13),0) -> 0 | I13: =IFERROR(C13/(C13+D13),0) -> 0
A14: Documents | B14: =COUNTIF('Test Cases'!$B$2:$B$336,$A14) -> 23 | C14: =COUNTIFS('Test Cases'!$B$2:$B$336,$A14,'Test Cases'!$K$2:$K$336,"Pass") -> 0 | D14: =COUNTIFS('Test Cases'!$B$2:$B$336,$A14,'Test Cases'!$K$2:$K$336,"Fail") -> 0 | E14: =COUNTIFS('Test Cases'!$B$2:$B$336,$A14,'Test Cases'!$K$2:$K$336,"Blocked") -> 0 | F14: =COUNTIFS('Test Cases'!$B$2:$B$336,$A14,'Test Cases'!$K$2:$K$336,"N/A") -> 0 | G14: =COUNTIFS('Test Cases'!$B$2:$B$336,$A14,'Test Cases'!$K$2:$K$336,"Not Run") -> 23 | H14: =IFERROR((B14-G14-F14)/(B14-F14),0) -> 0 | I14: =IFERROR(C14/(C14+D14),0) -> 0
A15: Users & Staff | B15: =COUNTIF('Test Cases'!$B$2:$B$336,$A15) -> 23 | C15: =COUNTIFS('Test Cases'!$B$2:$B$336,$A15,'Test Cases'!$K$2:$K$336,"Pass") -> 0 | D15: =COUNTIFS('Test Cases'!$B$2:$B$336,$A15,'Test Cases'!$K$2:$K$336,"Fail") -> 0 | E15: =COUNTIFS('Test Cases'!$B$2:$B$336,$A15,'Test Cases'!$K$2:$K$336,"Blocked") -> 0 | F15: =COUNTIFS('Test Cases'!$B$2:$B$336,$A15,'Test Cases'!$K$2:$K$336,"N/A") -> 0 | G15: =COUNTIFS('Test Cases'!$B$2:$B$336,$A15,'Test Cases'!$K$2:$K$336,"Not Run") -> 23 | H15: =IFERROR((B15-G15-F15)/(B15-F15),0) -> 0 | I15: =IFERROR(C15/(C15+D15),0) -> 0
A16: Roles & Permissions | B16: =COUNTIF('Test Cases'!$B$2:$B$336,$A16) -> 11 | C16: =COUNTIFS('Test Cases'!$B$2:$B$336,$A16,'Test Cases'!$K$2:$K$336,"Pass") -> 0 | D16: =COUNTIFS('Test Cases'!$B$2:$B$336,$A16,'Test Cases'!$K$2:$K$336,"Fail") -> 0 | E16: =COUNTIFS('Test Cases'!$B$2:$B$336,$A16,'Test Cases'!$K$2:$K$336,"Blocked") -> 0 | F16: =COUNTIFS('Test Cases'!$B$2:$B$336,$A16,'Test Cases'!$K$2:$K$336,"N/A") -> 0 | G16: =COUNTIFS('Test Cases'!$B$2:$B$336,$A16,'Test Cases'!$K$2:$K$336,"Not Run") -> 11 | H16: =IFERROR((B16-G16-F16)/(B16-F16),0) -> 0 | I16: =IFERROR(C16/(C16+D16),0) -> 0
... A22: Non-functional | B22: =COUNTIF('Test Cases'!$B$2:$B$336,$A22) -> 8 | C22: =COUNTIFS('Test Cases'!$B$2:$B$336,$A22,'Test Cases'!$K$2:$K$336,"Pass") -> 0 | D22: =COUNTIFS('Test Cases'!$B$2:$B$336,$A22,'Test Cases'!$K$2:$K$336,"Fail") -> 0 | E22: =COUNTIFS('Test Cases'!$B$2:$B$336,$A22,'Test Cases'!$K$2:$K$336,"Blocked") -> 0 | F22: =COUNTIFS('Test Cases'!$B$2:$B$336,$A22,'Test Cases'!$K$2:$K$336,"N/A") -> 0 | G22: =COUNTIFS('Test Cases'!$B$2:$B$336,$A22,'Test Cases'!$K$2:$K$336,"Not Run") -> 8 | H22: =IFERROR((B22-G22-F22)/(B22-F22),0) -> 0 | I22: =IFERROR(C22/(C22+D22),0) -> 0
A23: TOTAL | B23: =SUM(B5:B22) -> 335 | C23: =SUM(C5:C22) -> 0 | D23: =SUM(D5:D22) -> 0 | E23: =SUM(E5:E22) -> 0 | F23: =SUM(F5:F22) -> 0 | G23: =SUM(G5:G22) -> 335 | H23: =IFERROR((B23-G23-F23)/(B23-F23),0) -> 0 | I23: =IFERROR(C23/(C23+D23),0) -> 0
A26: High-priority cases
A27: High priority total | B27: =COUNTIF('Test Cases'!$E$2:$E$336,"High") -> 177
A28: High priority failed | B28: =COUNTIFS('Test Cases'!$E$2:$E$336,"High",'Test Cases'!$K$2:$K$336,"Fail") -> 0
A29: High priority not yet run | B29: =COUNTIFS('Test Cases'!$E$2:$E$336,"High",'Test Cases'!$K$2:$K$336,"Not Run") -> 177
A31: Open defects (Defect Log)
A32: Open (New, In Progress, Reopened, Retest Failed) | B32: =COUNTIF('Defect Log'!$I$6:$I$500,"New")+COUNTIF('Defect Log'!$I$6:$I$500,"In Progress")+COUNTIF('Defect Log'!$I$6:$I$500,"Reopened")+COUNTIF('Defect Log'!$I$6:$I$500,"Retest Failed") -> 0
A33: Critical / High severity still open | B33: =COUNTIFS('Defect Log'!$H$6:$H$500,"Critical",'Defect Log'!$I$6:$I$500,"<>Closed",'Defect Log'!$I$6:$I$500,"<>Fixed",'Defect Log'!$I$6:$I$500,"<>")+COUNTIFS('Defect Log'!$H$6:$H$500,"High",'Defect Log'!$I$6:$I$500,"<>Closed",'Defect Log'!$I$6:$I$500,"<>Fixed",'Defect Log'!$I$6:$I$500,"<>") -> 0

Sheet Test Cases
A1: Test ID | B1: Module | C1: Feature / Area | D1: Type | E1: Priority | F1: Log in as | G1: Preconditions / Data | H1: Steps | I1: Expected Result | J1: Actual Result | K1: Status | L1: Tested By | M1: Date Tested | N1: Defect ID | O1: Comments
A2: LOG-01 | B2: Login & Layout | C2: Access control | D2: Negative | E2: High | F2: None | G2: Logged out | H2: Open the app root URL | I2: Redirected to the login page | K2: Not Run
A3: LOG-02 | B3: Login & Layout | C3: Access control | D3: Negative | E3: High | F3: None | G3: Logged out | H3: Open /students directly | I3: Redirected to the login page; no student data visible | K3: Not Run
A4: LOG-03 | B4: Login & Layout | C4: Login | D4: Functional | E4: High | F4: Admin | G4: Valid Admin account | H4: Enter username + correct password, Sign in | I4: Dashboard opens; header shows 'Welcome, <username>' | K4: Not Run
A5: LOG-04 | B5: Login & Layout | C5: Login | D5: Functional | E5: Medium | F5: Admin | G5: Valid Admin account | H5: Log in using the e-mail address instead of the username | I5: Login works | K5: Not Run
A6: LOG-05 | B6: Login & Layout | C6: Login | D6: Negative | E6: High | F6: None | H6: Enter a wrong password | I6: Message 'Invalid username/email or password.'; stays on login; button usable again | K6: Not Run
A7: LOG-06 | B7: Login & Layout | C7: Login | D7: Validation | E7: Medium | F7: None | H7: Submit the empty form | I7: Fields flagged / message shown; no crash | K7: Not Run
A8: LOG-07 | B8: Login & Layout | C8: Login | D8: UI | E8: Low | F8: None | H8: Click Sign in twice quickly | I8: Button disabled while submitting; only one request sent | K8: Not Run
A9: LOG-08 | B9: Login & Layout | C9: Session | D9: Functional | E9: High | F9: Admin | G9: Logged in | H9: Refresh the browser page | I9: Still logged in | K9: Not Run
A10: LOG-09 | B10: Login & Layout | C10: Session | D10: Negative | E10: Medium | F10: Admin | G10: Logged in | H10: Clear the saved session (browser storage) and navigate to any page | I10: Redirected to login | K10: Not Run
A11: LOG-10 | B11: Login & Layout | C11: Session | D11: Negative | E11: Medium | F11: Admin | G11: Logged in | H11: Let the session expire (or edit expiry to the past in storage) and reload | I11: Session cleared and login shown | K11: Not Run
A12: LOG-11 | B12: Login & Layout | C12: Session | D12: Negative | E12: Medium | F12: Admin | G12: Logged in | H12: Tamper with the saved token, then open any list | I12: App redirects to login automatically | K12: Not Run
A13: LOG-12 | B13: Login & Layout | C13: Session | D13: Functional | E13: High | F13: Admin | G13: Logged in | H13: Click Logout in the sidebar, then press the browser Back button | I13: Back at login; Back button does not show protected pages | K13: Not Run
A14: LOG-13 | B14: Login & Layout | C14: Login | D14: Security | E14: High | F14: Any | G14: Account with a few wrong attempts | H14: Enter the wrong password repeatedly (about 5 times) for one account | I14: Account becomes locked with a clear message; correct password is refused until an Admin unlocks (see USR-15) | K14: Not Run
A15: LOG-14 | B15: Login & Layout | C15: Login | D15: Security | E15: High | F15: Any | G15: User whose status is Inactive or Suspended | H15: Try to log in | I15: Login refused with a clear message | K15: Not Run
A16: LOG-15 | B16: Login & Layout | C16: Login | D16: Functional | E16: High | F16: Any | G16: User created by Admin (MustChangePassword) | H16: Log in with the temporary password | I16: Forced to the Change Password page; no other page is reachable until the password is changed | K16: Not Run
A17: LAY-01 | B17: Login & Layout | C17: Layout | D17: UI | E17: Medium | F17: Admin | G17: Logged in | H17: Look at the sidebar | I17: Sections visible (Overview, Records, Daily, ...); current page highlighted | K17: Not Run
A18: LAY-02 | B18: Login & Layout | C18: Layout | D18: Functional | E18: High | F18: Admin | G18: Logged in | H18: Click each built item: Dashboard, Admissions, Students, Classes & Sections, Parents, Subjects, Teachers, Attendance, Documents, Users & Staff, Roles & Permissions, My Account, Settings | I18: Correct page opens; URL changes | K18: Not Run
A19: LAY-03 | B19: Login & Layout | C19: Layout | D19: Functional | E19: Low | F19: Admin | G19: Logged in | H19: Click a module that is not built yet (e.g. Reports, Timetable, Fees) | I19: Redirects to the dashboard with no error (known placeholder) | K19: Not Run
A20: LAY-04 | B20: Login & Layout | C20: Layout | D20: UI | E20: Low | F20: Admin | G20: Logged in | H20: Toggle dark mode on several pages, refresh | I20: Theme switches, all pages readable in both themes, choice survives refresh | K20: Not Run
... A24: LAY-08 | B24: Login & Layout | C24: Layout | D24: Security | E24: High | F24: Clerk | G24: Clerk logged in | H24: Look at the sidebar and try URLs of pages the role may not use (e.g. /roles-permissions, /settings) | I24: Items the user may not use are hidden or the page shows a clear 'no permission' state; no data from the page is shown | K24: Not Run
A25: CMP-01 | B25: Reusable Components | C25: Validation modal | D25: UI | E25: High | F25: Any | H25: Trigger a server validation error on any form | I25: Modal lists every server message; closes with button / X; no raw JSON shown | K25: Not Run
A26: CMP-02 | B26: Reusable Components | C26: Validation modal | D26: UI | E26: High | F26: Any | H26: Trigger a business-rule error (e.g. class is full) | I26: Server message shown clearly (e.g. 'is full (1/1)') | K26: Not Run
A27: CMP-03 | B27: Reusable Components | C27: Confirm dialog | D27: Functional | E27: High | F27: Any | H27: Open any delete confirmation; Cancel, then repeat and Confirm | I27: Cancel keeps data; Confirm does the action exactly once | K27: Not Run
A28: CMP-04 | B28: Reusable Components | C28: Details modal | D28: UI | E28: Medium | F28: Any | H28: Open any View (eye) modal | I28: All sections shown; empty values show a dash; closes cleanly | K28: Not Run
A29: CMP-05 | B29: Reusable Components | C29: Table footer / paging | D29: Functional | E29: High | F29: Any | G29: List with >25 rows | H29: Check footer text; change page size 10/25/50; use Prev/Next | I29: 'Showing x-y of N' correct; page size changes rows; Prev/Next disabled at the ends | K29: Not Run
A30: CMP-06 | B30: Reusable Components | C30: Quick search | D30: Functional | E30: Medium | F30: Any | H30: Type in the search box above a table | I30: Rows filter live; paging resets to page 1 | K30: Not Run
A31: CMP-07 | B31: Reusable Components | C31: Export CSV | D31: Functional | E31: Medium | F31: Any | H31: Filter a list, click Export CSV, open in Excel | I31: File downloads; header + rows match what is filtered on screen; special characters/commas not broken | K31: Not Run
A32: CMP-08 | B32: Reusable Components | C32: Modals | D32: UI | E32: Low | F32: Any | H32: Open a modal; press Esc; scroll the page behind | I32: Esc/X closes where supported; background does not scroll; focus lands in first field | K32: Not Run
A33: CMP-09 | B33: Reusable Components | C33: Error state | D33: Negative | E33: Medium | F33: Any | G33: API stopped | H33: Open a list page while the API is down | I33: Error message or error state; not a blank page or endless spinner | K33: Not Run
A34: CMP-10 | B34: Reusable Components | C34: Toasts | D34: UI | E34: Low | F34: Any | H34: Save something successfully; also cause an error | I34: Success/error toast appears and disappears; text is understandable | K34: Not Run
A35: CLS-01 | B35: Class Sections | C35: List | D35: Functional | E35: High | F35: Admin | G35: Logged in | H35: Open Classes & Sections | I35: List loads; Academic Year, Section, Stage, Medium filters are populated | K35: Not Run
A36: CLS-02 | B36: Class Sections | C36: Create | D36: Validation | E36: High | F36: Admin | H36: Click Add Class, leave all empty, Save | I36: Required-field messages; nothing created | K36: Not Run
A37: CLS-03 | B37: Class Sections | C37: Create | D37: Functional | E37: High | F37: Admin | H37: Add Name 'ZT Class', Section 'A', Stage Primary, Medium English, Stream General, Capacity 30 | I37: Created; appears with display name like 'ZT Class A (2026-2027)'; code auto-generated | K37: Not Run
A38: CLS-04 | B38: Class Sections | C38: Create | D38: Negative | E38: High | F38: Admin | G38: ZT Class A exists | H38: Add the same class again | I38: Error about duplicate; nothing created | K38: Not Run
A39: CLS-05 | B39: Class Sections | C39: Create | D39: Validation | E39: Medium | F39: Admin | H39: Capacity 0 and 201; Grade 13; Floor 21 | I39: Each gives a validation message | K39: Not Run
A40: CLS-06 | B40: Class Sections | C40: Create | D40: Functional | E40: Low | F40: Admin | H40: Leave Grade blank (LKG/UKG case) | I40: Accepted | K40: Not Run
A41: CLS-07 | B41: Class Sections | C41: Edit | D41: Functional | E41: Medium | F41: Admin | H41: Edit a class, change Room, Save | I41: Saved; reflected in the list | K41: Not Run
A42: CLS-08 | B42: Class Sections | C42: Edit | D42: Negative | E42: High | F42: Admin | G42: Class with students | H42: Lower capacity below current student count | I42: Error 'Capacity cannot be lower than the current strength' | K42: Not Run
A43: CLS-09 | B43: Class Sections | C43: Status | D43: Functional | E43: High | F43: Admin | H43: Set the class Inactive | I43: Row shows Inactive; class no longer appears in admission / student / enrol class lists | K43: Not Run
...

Sheet Test Data
A1: Test data to set up first
A2: Create these in a TEST database. Passwords are suggestions: change them if your policy differs (8+ characters, upper case, digit, special character).
A4: Username | B4: Role | C4: Suggested password | D4: Notes
A5: admin | B5: Admin | C5: (existing admin) | D5: Full access. Use for most cases.
A6: admin2 | B6: Admin | C6: ZtAdmin#2026 | D6: Second Admin: needed for document review (no self-review), concurrency and 'last Admin' cases.
A7: zt.clerk | B7: Clerk | C7: ZtClerk#2026 | D7: Limited role. Used for permission and masking cases.
A8: zt.supervisor | B8: Supervisor | C8: ZtSuper#2026 | D8: Limited role; can see identity values.
A9: zt.teacher1 | B9: Teacher | C9: ZtTeach#2026 | D9: Class teacher of 'ZT Class A' (assign it in Teachers). Used for attendance and scoped-access cases.
A10: zt.custom | B10: Custom role 'ZT NoParents' | C10: ZtCustom#2026 | D10: Create a role with Admissions.Create/Edit but WITHOUT Parents.View (cases ADM-G09, G10). Also create 'ZT ParentsOnly' with Parents.View but no Admissions rights (ADM-G11).
A12: Sample records
A13: Record | B13: Name / value | C13: Details | D13: Notes
A14: Class | B14: ZT Class A | C14: Section A, Primary, English, General, capacity 30 | D14: Second class: ZT Class B. For 'full' tests make one with capacity 1.
A15: Subject | B15: ZT Math | C15: Class A, Theory, max 100, pass 35
A16: Parent | B16: ZT Father | C16: Mobile 9876501111 | D16: Used in E2E-01, E2E-06 and the existing-parent cases.
A17: Parent | B17: ZT Mother | C17: Mobile 9876502222
A18: Applicant | B18: ZTKid One | C18: DOB a valid past date, Class A | D18: Guardians: Father (mobile 9876501111) and Mother.
A19: Documents | B19: small.pdf, photo.jpg, scan.png | C19: Any small files | D19: Also: a text file renamed .pdf (must be refused) and a file over 5 MB.
A20: Time | B20: Test around midnight | C20: 00:00-04:00 Abu Dhabi | D20: For case ATT-25 only.

Sheet Defect Log
A1: Defect Log
A2: One row per defect. Row 5 is an EXAMPLE (not counted in the Summary) showing the expected level of detail: overwrite or delete it. Copy the Defect ID into the failing test row. | L2: Severity: Critical = data loss / security / cannot continue; High = core feature broken; Medium = workaround exists; Low = cosmetic.
A4: Defect ID | B4: Date Found | C4: Module | D4: Test ID | E4: Summary (one line) | F4: Steps to reproduce | G4: Expected vs Actual | H4: Severity | I4: Status | J4: Reported By | K4: Screenshot / File | L4: Developer Notes
A5: DEF-001 | B5: 2026-10-15 | C5: Students | D5: STU-25 | E5: EXAMPLE: Moving a student to another class does not add a history row | F5: 1. Login as Admin 2. Students > Edit 'ZTKid One' 3. Change class A to B, Save 4. Open Academic History | G5: Expected: two rows (Transferred + Active). Actual: one row only. Console shows no error. | H5: High | I5: New | J5: Tester name | K5: screenshot-001.png
